{"uuid": "526b3530-6322-4587-a312-abdb99e4fcd6", "children": ["e67ebea9-6f07-4195-88cc-112841253113"], "befores": [{"name": "appium_driver_setup_teardown", "status": "broken", "statusDetails": {"message": "selenium.common.exceptions.WebDriverException: Message: An unknown server-side error occurred while processing the command. Original error: Neither ANDROID_HOME nor ANDROID_SDK_ROOT environment variable was exported. Read https://developer.android.com/studio/command-line/variables for more details\nStacktrace:\nUnknownError: An unknown server-side error occurred while processing the command. Original error: Neither ANDROID_HOME nor ANDROID_SDK_ROOT environment variable was exported. Read https://developer.android.com/studio/command-line/variables for more details\n    at getResponseForW3CError (/Users/sayantan/.nvm/versions/node/v22.7.0/lib/node_modules/appium/node_modules/@appium/base-driver/lib/protocol/errors.js:1145:9)\n    at asyncHandler (/Users/sayantan/.nvm/versions/node/v22.7.0/lib/node_modules/appium/node_modules/@appium/base-driver/lib/protocol/protocol.js:485:57)\n", "trace": "  File \"/Users/sayantan/PycharmProjects/Appium-Python-Android-Pytest_Project/.venv/lib/python3.12/site-packages/pluggy/_callers.py\", line 167, in _multicall\n    teardown.throw(outcome._exception)\n  File \"/Users/sayantan/PycharmProjects/Appium-Python-Android-Pytest_Project/.venv/lib/python3.12/site-packages/_pytest/setuponly.py\", line 36, in pytest_fixture_setup\n    return (yield)\n            ^^^^^\n  File \"/Users/sayantan/PycharmProjects/Appium-Python-Android-Pytest_Project/.venv/lib/python3.12/site-packages/pluggy/_callers.py\", line 103, in _multicall\n    res = hook_impl.function(*args)\n          ^^^^^^^^^^^^^^^^^^^^^^^^^\n  File \"/Users/sayantan/PycharmProjects/Appium-Python-Android-Pytest_Project/.venv/lib/python3.12/site-packages/_pytest/fixtures.py\", line 1139, in pytest_fixture_setup\n    result = call_fixture_func(fixturefunc, request, kwargs)\n             ^^^^^^^^^^^^^^^^^^^^^^^^^^^^^^^^^^^^^^^^^^^^^^^\n  File \"/Users/sayantan/PycharmProjects/Appium-Python-Android-Pytest_Project/.venv/lib/python3.12/site-packages/_pytest/fixtures.py\", line 890, in call_fixture_func\n    fixture_result = next(generator)\n                     ^^^^^^^^^^^^^^^\n  File \"/Users/sayantan/Documents/git/AppiumProjects/Appium-Python-Android-Pytest_Project/Appium-Python-Android-Pytest/src/conftest.py\", line 68, in appium_driver_setup_teardown\n    driver = webdriver.Remote(url, options=options)\n             ^^^^^^^^^^^^^^^^^^^^^^^^^^^^^^^^^^^^^^\n  File \"/Users/sayantan/PycharmProjects/Appium-Python-Android-Pytest_Project/.venv/lib/python3.12/site-packages/appium/webdriver/webdriver.py\", line 229, in __init__\n    super().__init__(\n  File \"/Users/sayantan/PycharmProjects/Appium-Python-Android-Pytest_Project/.venv/lib/python3.12/site-packages/selenium/webdriver/remote/webdriver.py\", line 212, in __init__\n    self.start_session(capabilities)\n  File \"/Users/sayantan/PycharmProjects/Appium-Python-Android-Pytest_Project/.venv/lib/python3.12/site-packages/appium/webdriver/webdriver.py\", line 319, in start_session\n    response = self.execute(RemoteCommand.NEW_SESSION, w3c_caps)\n               ^^^^^^^^^^^^^^^^^^^^^^^^^^^^^^^^^^^^^^^^^^^^^^^^^\n  File \"/Users/sayantan/PycharmProjects/Appium-Python-Android-Pytest_Project/.venv/lib/python3.12/site-packages/selenium/webdriver/remote/webdriver.py\", line 354, in execute\n    self.error_handler.check_response(response)\n  File \"/Users/sayantan/PycharmProjects/Appium-Python-Android-Pytest_Project/.venv/lib/python3.12/site-packages/selenium/webdriver/remote/errorhandler.py\", line 229, in check_response\n    raise exception_class(message, screen, stacktrace)\n"}, "start": 1727410358933, "stop": 1727410359723}], "start": 1727410358933, "stop": 1727410359972}